<?xml version="1.0" ?>
<!-- =================================================================================== -->
<!-- |    This document was autogenerated by xacro from robot.urdf.xacro               | -->
<!-- |    EDITING THIS FILE BY HAND IS NOT RECOMMENDED                                 | -->
<!-- =================================================================================== -->
<robot name="differential_drive_robot">
  <!-- =========== Inertia Calculation for Wheel =========== -->
  <link name="ball_collector_link">
    <visual>
      <origin rpy="0 -3.141592265 0" xyz="0.08 -0.114 0.38"/>
      <geometry>
        <mesh filename="file:///home/rajana/gazebo_ws/install/gcr_diff_robot/share/gcr_diff_robot/meshes/ball_collector.STL" scale="0.001 0.001 0.001"/>
      </geometry>
      <material name="blue">
        <color rgba="0 0 .8 1"/>
      </material>
    </visual>
    <collision name="ball_collector_collision">
      <origin rpy="0 -3.141592265 0" xyz="0.08 -0.114 0.38"/>
      <geometry>
        <mesh filename="file:///home/rajana/gazebo_ws/install/gcr_diff_robot/share/gcr_diff_robot/meshes/ball_collector.STL" scale="0.001 0.001 0.001"/>
      </geometry>
    </collision>
    <inertial>
      <origin rpy="0 0 0" xyz="0 0 0.14"/>
      <mass value="0.6"/>
      <inertia ixx="0.002" ixy="0.0" ixz="0.0" iyy="0.002" iyz="0.0" izz="0.003"/>
    </inertial>
  </link>
  <joint name="ball_collector_joint" type="revolute">
    <parent link="body_link"/>
    <child link="ball_collector_link"/>
    <origin rpy="0 0 0" xyz="0.355 0 0"/>
    <axis xyz="0 1 0"/>
    <limit effort="10.0" lower="0" upper="1.5707961325" velocity="5.0"/>
    <dynamics damping="0.1" friction="0.05"/>
  </joint>
  <!-- Ball Collector Properties-->
  <gazebo reference="ball_collector_link">
    <material>Gazebo/Blue</material>
    <mu1>0.2</mu1>
    <mu2>0.2</mu2>
    <sensor name="ball_collector_contact_sensor" type="contact">
      <update_rate>50</update_rate>
      <contact>
        <collision>ball_collector_collision_collision</collision>
      </contact>
      <plugin filename="libgazebo_ros_bumper.so" name="contact_plugin">
        <ros>
          <namespace>gcr</namespace>
          <remapping>bumper_states:=contact_sensor_topic</remapping>
        </ros>
        <frame_name>ball_collector_link</frame_name>
      </plugin>
    </sensor>
  </gazebo>
  <!-- Body Link Properties -->
  <gazebo reference="body_link">
    <material>Gazebo/Green</material>
    <mu1>0.2</mu1>
    <mu2>0.2</mu2>
  </gazebo>
  <!-- Visual Model Link Properties -->
  <gazebo reference="visual_model_link">
    <material>Gazebo/OrangeTransparent</material>
  </gazebo>
  <!-- Heavy Link Properties -->
  <gazebo reference="heavy_link">
    <material>Gazebo/Blue</material>
    <mu1>0.2</mu1>
    <mu2>0.2</mu2>
  </gazebo>
  <!-- Wheel 1 Link Properties -->
  <gazebo reference="wheel1_link">
    <material>Gazebo/Runway</material>
    <mu1>2.0</mu1>
    <mu2>2.0</mu2>
  </gazebo>
  <!-- Wheel 2 Link Properties -->
  <gazebo reference="wheel2_link">
    <material>Gazebo/Runway</material>
    <mu1>2.0</mu1>
    <mu2>2.0</mu2>
  </gazebo>
  <!-- Caster Wheel Link Properties -->
  <gazebo reference="caster_wheel_link">
    <material>Gazebo/Indigo</material>
    <mu1>0.2</mu1>
    <mu2>0.2</mu2>
  </gazebo>
  <!-- Controller for Differential Drive Robot -->
  <gazebo>
    <plugin filename="libgazebo_ros_diff_drive.so" name="diff_drive_plugin">
      <ros>
        <!-- Namespace for the plugin (leave empty for default) -->
        <namespace/>
      </ros>
      <!-- Joint Names for Left and Right Wheels -->
      <left_joint>wheel2_joint</left_joint>
      <right_joint>wheel1_joint</right_joint>
      <!-- Kinematic Parameters -->
      <wheel_separation>0.28</wheel_separation>
      <wheel_diameter>0.16</wheel_diameter>
      <!-- Torque and Acceleration Limits -->
      <max_wheel_torque>1000</max_wheel_torque>
      <max_wheel_acceleration>5.0</max_wheel_acceleration>
      <!-- Output Configuration -->
      <publish_odom>true</publish_odom>
      <publish_odom_tf>true</publish_odom_tf>
      <publish_wheel_tf>true</publish_wheel_tf>
      <!-- Frame Names -->
      <odometry_frame>odom</odometry_frame>
      <robot_base_frame>dummy_link</robot_base_frame>
    </plugin>
  </gazebo>
  <!-- Camera of Robot & Joint -->
  <link name="camera_link">
    <visual>
      <geometry>
        <box size="0.02 0.03 0.03"/>
      </geometry>
    </visual>
    <collision>
      <geometry>
        <box size="0.02 0.03 0.03"/>
      </geometry>
    </collision>
    <inertial>
      <origin rpy="0 0 0" xyz="0 0 0"/>
      <mass value="0.01"/>
      <inertia ixx="1.0833333333333333e-06" ixy="0" ixz="0" iyy="1.0833333333333333e-06" iyz="0" izz="1.4999999999999998e-06"/>
    </inertial>
  </link>
  <joint name="camera_joint" type="revolute">
    <parent link="body_link"/>
    <child link="camera_link"/>
    <origin rpy="0 0 0" xyz="0.3 0 0.56"/>
    <axis xyz="0 1 0"/>
    <limit effort="10.0" lower="-1.5707961325" upper="1.5707961325" velocity="5.0"/>
    <dynamics damping="0.1" friction="0.05"/>
  </joint>
  <!-- <transmission name="transmission_camera_joint">
        <plugin>transmission_interface/SimpleTransmission</plugin>
        <actuator name="motor_body_camera_joint" role="actuator1" />
        <joint name="camera_joint" role="joint1">
            <mechanical_reduction>1.0</mechanical_reduction>
        </joint>
    </transmission> -->
  <!-- Camera Sensor  Gazebo-->
  <gazebo reference="camera_link">
    <material>Gazebo/Green</material>
    <sensor name="camera_sensor" type="camera">
      <pose>0 0 0 0 0 0</pose>
      <visualize>true</visualize>
      <update_rate>30</update_rate>
      <camera>
        <horizontal_fov>1.57</horizontal_fov>
        <image>
          <width>640</width>
          <height>480</height>
          <format>R8G8B8</format>
        </image>
      </camera>
      <plugin filename="libgazebo_ros_camera.so" name="camera_controller">
        <imageTopicName>image_raw</imageTopicName>
        <cameraInfoTopicName>camera_info</cameraInfoTopicName>
        <frameName>camera_link</frameName>
      </plugin>
    </sensor>
  </gazebo>
  <!-- Gazebo ros2_control plugin -->
  <gazebo>
    <plugin filename="libgazebo_ros2_control.so" name="gazebo_ros2_control">
      <robot_param>robot_description</robot_param>
      <robot_param_node>robot_state_publisher</robot_param_node>
      <parameters>/home/rajana/gazebo_ws/install/gcr_controller/share/gcr_controller/config/gcr_controllers.yaml</parameters>
    </plugin>
  </gazebo>
  <ros2_control name="RobotSystem" type="system">
    <!-- ros2_control Gazebo -->
    <hardware>
      <plugin>gazebo_ros2_control/GazeboSystem</plugin>
    </hardware>
    <joint name="camera_joint">
      <command_interface name="position">
        <param name="min">-1.570796326795</param>
        <param name="max">1.570796326795</param>
      </command_interface>
      <state_interface name="position"/>
    </joint>
    <joint name="ball_collector_joint">
      <command_interface name="position">
        <param name="min">0</param>
        <param name="max">3.14159265359</param>
      </command_interface>
      <state_interface name="position"/>
    </joint>
  </ros2_control>
  <!-- ==================== Links and Joints ==================== -->
  <link name="dummy_link"/>
  <!-- Main Body Link of Robot -->
  <link name="body_link">
    <visual>
      <geometry>
        <box size="0.68 0.28 0.04"/>
      </geometry>
      <origin rpy="0 0 0" xyz="0 0 0"/>
    </visual>
    <collision>
      <geometry>
        <box size="0.68 0.28 0.04"/>
      </geometry>
      <origin rpy="0 0 0" xyz="0 0 0"/>
    </collision>
    <inertial>
      <origin rpy="0 0 0" xyz="0 0 0"/>
      <mass value="3.8080000000000003"/>
      <inertia ixx="0.025386666666666672" ixy="0" ixz="0" iyy="0.14724266666666672" iyz="0" izz="0.1716138666666667"/>
    </inertial>
  </link>
  <joint name="dummy_to_body_joint" type="fixed">
    <parent link="dummy_link"/>
    <child link="body_link"/>
    <origin xyz="0 0 0.08"/>
  </joint>
  <!-- Visual Model Link and Joint -->
  <!-- <joint name="visual_model_joint" type="fixed">
        <parent link="body_link"/>
        <child link="visual_model_link"/>
        <origin xyz="0 0 0" rpy="0 0 0"/>
    </joint>

    <link name="visual_model_link">
        <visual>
            <geometry>
                <mesh filename="package://gcr_diff_robot/meshes/gcr_mesh.STL" scale="0.001 0.001 0.001"/>
            </geometry>
            <origin rpy="1.570795 0 -1.570795" xyz="0 0 0.25"/>
        </visual>
    </link> -->
  <!-- Heavy Link of Robot & Joint -->
  <joint name="heavy_joint" type="fixed">
    <parent link="body_link"/>
    <child link="heavy_link"/>
    <origin rpy="0 0 0" xyz="0.23 0 0.02"/>
  </joint>
  <link name="heavy_link">
    <visual>
      <geometry>
        <box size="0.06 0.2 0.54"/>
      </geometry>
      <origin rpy="0 0 0" xyz="0 0 0.27"/>
    </visual>
    <collision>
      <geometry>
        <box size="0.06 0.2 0.54"/>
      </geometry>
      <origin rpy="0 0 0" xyz="0 0 0.27"/>
    </collision>
    <inertial>
      <origin rpy="0 0 0" xyz="0 0 0.27"/>
      <mass value="6.091200000000001"/>
      <inertia ixx="0.16832016000000002" ixy="0" ixz="0" iyy="0.14984352000000004" iyz="0" izz="0.022131360000000006"/>
    </inertial>
  </link>
  <!-- Front Right Wheel of Robot & Joint -->
  <joint name="wheel1_joint" type="continuous">
    <parent link="body_link"/>
    <child link="wheel1_link"/>
    <origin rpy="0 0 0" xyz="0.26 -0.165 0"/>
    <axis xyz="0 1 0"/>
    <limit effort="100" velocity="10"/>
    <dynamics damping="1.0" friction="1.0"/>
  </joint>
  <link name="wheel1_link">
    <visual>
      <origin rpy="1.570795 0 0" xyz="0 0 0"/>
      <geometry>
        <cylinder length="0.05" radius="0.08"/>
      </geometry>
    </visual>
    <collision>
      <origin rpy="1.570795 0 0" xyz="0 0 0"/>
      <geometry>
        <cylinder length="0.05" radius="0.08"/>
      </geometry>
    </collision>
    <inertial>
      <origin rpy="0 0 0" xyz="0 0 0"/>
      <mass value="1.0053095248000001"/>
      <inertia ixx="0.0018179347240133332" ixy="0.0" ixz="0.0" iyy="0.0032169904793600008" iyz="0" izz="0.0018179347240133332"/>
    </inertial>
  </link>
  <!-- Front Left Wheel of Robot & Joint -->
  <joint name="wheel2_joint" type="continuous">
    <parent link="body_link"/>
    <child link="wheel2_link"/>
    <origin rpy="0 0 0" xyz="0.26 0.165 0"/>
    <axis xyz="0 1 0"/>
    <limit effort="100" velocity="10"/>
    <dynamics damping="1.0" friction="1.0"/>
  </joint>
  <link name="wheel2_link">
    <visual>
      <origin rpy="1.570795 0 0" xyz="0 0 0"/>
      <geometry>
        <cylinder length="0.05" radius="0.08"/>
      </geometry>
    </visual>
    <collision>
      <origin rpy="1.570795 0 0" xyz="0 0 0"/>
      <geometry>
        <cylinder length="0.05" radius="0.08"/>
      </geometry>
    </collision>
    <inertial>
      <origin rpy="0 0 0" xyz="0 0 0"/>
      <mass value="1.0053095248000001"/>
      <inertia ixx="0.0018179347240133332" ixy="0.0" ixz="0.0" iyy="0.0032169904793600008" iyz="0" izz="0.0018179347240133332"/>
    </inertial>
  </link>
  <!-- Caster Wheel of Robot & Joint -->
  <joint name="caster_wheel_joint" type="fixed">
    <parent link="body_link"/>
    <child link="caster_wheel_link"/>
    <origin rpy="0 0 0" xyz="-0.26 0 0"/>
  </joint>
  <link name="caster_wheel_link">
    <visual>
      <origin rpy="0 0 0" xyz="0 0 0"/>
      <geometry>
        <sphere radius="0.08"/>
      </geometry>
    </visual>
    <collision>
      <origin rpy="0 0 0" xyz="0 0 0"/>
      <geometry>
        <sphere radius="0.08"/>
      </geometry>
    </collision>
    <inertial>
      <origin rpy="0 0 0" xyz="0 0 0"/>
      <mass value="2.1392986687744"/>
      <inertia ixx="0.005476604592062464" ixy="0" ixz="0" iyy="0.005476604592062464" iyz="0" izz="0.005476604592062464"/>
    </inertial>
  </link>
</robot>
